Workbook

Sheet P&L
A1: KRTRIMAIQ COGNITIVE SOLUTIONS
A2: (Partnership Firm)
A3: (Address: No. 98/A 3Rd Floor, 30Th Cross,7Th Block Jayanagar, Bangalore, KARNATAKA - 560082)
A4: Balance Sheet as at 31 March 2026
A5: Statement of Profit and loss for the year ended 31 March 2026
D6: (In Rs)
A7: Particulars | B7: Note | C7: 46112 | D7: 45747
A9: Revenue from Operations | B9: =Notes!A223 -> 10 | C9: =Notes!$I$229 -> 56778956 | D9: =Notes!$J$229 -> 0
A10: Other Income | B10: =Notes!A232 -> 11 | C10: =Notes!$I$238 -> 198358.69 | D10: =Notes!$J$238 -> 0
A11: Total Income | C11: =SUM(C9:C10) -> 56977315 | D11: =SUM(D9:D10) -> 0
A13: Expenses
A14: Employee Benefit Expenses | B14: =Notes!A241 -> 12 | C14: =Notes!$I$249 -> 40189768 | D14: =Notes!$J$249 -> 0
A15: Finance Costs | B15: =Notes!A252 -> 13 | C15: =Notes!$I$257 -> 27071.62 | D15: =Notes!$J$257 -> 0
A16: Depreciation and Amortization Expenses | B16: =Notes!A260 -> 14 | C16: =Notes!$I$265 -> 0 | D16: =Notes!$J$265 -> 0
A17: Other Expenses | B17: =Notes!A268 -> 15 | C17: =Notes!$I$299 -> 10177874 | D17: =Notes!$J$299 -> 0
A18: Total expenses | C18: =SUM(C14:C17) -> 50394714 | D18: =SUM(D14:D17) -> 0
A20: Profit/(Loss) before Exceptional and Extraordinary Item and Tax | C20: =C11-C18 -> 6582601.3 | D20: =D11-D18 -> 0
A21: Exceptional Item | C21: 0 | D21: 0
A22: Profit/(Loss) before Extraordinary Item and Tax | C22: =C20-C21 -> 6582601.3 | D22: =D20-D21 -> 0
A23: Extraordinary Item | C23: 0 | D23: 0
A24: Profit/(Loss) before Tax | C24: =C22-C23 -> 6582601.3 | D24: =D22-D23 -> 0
A25: Tax Expenses | B25: =Notes!A302 -> 16
A26: - Current Tax | C26: =Notes!$I$305 -> 0 | D26: =Notes!$J$305 -> 0
A27: - Deferred Tax | C27: =Notes!$I$306 -> 0 | D27: =Notes!$J$306 -> 0
A28: Profit/(Loss) after Tax | C28: =C24-C26-C27 -> 6582601.3 | D28: =D24-D26-D27 -> 0
A29: Earnings Per Share (Face Value per Share Rs.10 each)
A30: -Basic (In Rs)
A31: -Diluted (In Rs)
A33: See accompanying notes to the financial statements
A35: As per our report of even date | D35: For and on behalf of the Partners of
A36: For R.K.Tantry & Co., | D36: KRTRIMAIQ COGNITIVE SOLUTIONS
A37: Chartered Accountants
A38: Firm's Registration No. 004335S
A42: Radhakrishna Tantry | B42: SRINIVAS RAO POLADI
A43: Partner | B43: PARTNER
A44: Membership No. 024012
A45: UDIN:
A46: Place: Bangalore | D46: Place: Bangalore
A47: Date: | D47: Date:

Sheet BS
A1: KRTRIMAIQ COGNITIVE SOLUTIONS
A2: (Partnership Firm)
A3: (Address: No. 98/A 3Rd Floor, 30Th Cross,7Th Block Jayanagar, Bangalore, KARNATAKA - 560082)
A4: Balance Sheet as at 31 March 2026
D5: (In Rs)
A6: Particulars | B6: Note | C6: 46112 | D6: 45747
A8: I. EQUITY AND LIABILITIES
A9: (1) Partners' funds
A10: (a) Capital Account | B10: =Notes!A6 -> 1 | C10: =Notes!$I$15 -> -6761000.4 | D10: =Notes!$J$15 -> 0
A11: (b) Profit and Loss Account | B11: =Notes!A18 -> 2 | C11: =Notes!$I$23 -> 6582601.3 | D11: =Notes!$J$23 -> 0
A12: Total | C12: =SUM(C10:C11) -> -178399.09 | D12: =SUM(D10:D11) -> 0 | E12: 218775
A14: (2) Non-current liabilities
A15: (a) Long-term Borrowings | B15: =Notes!A26 -> 3 | C15: =Notes!$I$31 -> 5100000 | D15: =Notes!$J$31 -> 0
A16: Total | C16: =SUM(C15:C15) -> 5100000 | D16: =SUM(D15:D15) -> 0
A18: (3) Current liabilities
A19: (a) Trade Payables | B19: =Notes!A34 -> 4
A20: - Due to Micro and Small Enterprises | C20: 0 | D20: 0
A21: - Due to Others | C21: =Notes!$I$84 -> 523219.09 | D21: =Notes!$J$84 -> 0
A22: (b) Short-term Provisions and Statutory Liabilities | B22: =Notes!A87 -> 5 | C22: =Notes!$I$141 -> 6149763.8 | D22: =Notes!$J$141 -> 0
A23: Total | C23: =SUM(C20:C22) -> 6672982.9 | D23: =SUM(D20:D22) -> 0
A24: Total Equity and Liabilities | C24: =SUM(C12,C16,C23) -> 11594584 | D24: =SUM(D12,D16,D23) -> 0
A26: II. ASSETS
A27: (1) Non-current assets
A28: (a) Property, Plant and Equipment and Intangible Assets
A29: (i) Property, Plant and Equipment | B29: =Notes!A144 -> 6 | C29: =Notes!$I$149 -> 1234104.9 | D29: =Notes!$J$149 -> 0
A30: (b) Non-current Investments | C30: =Notes!$I$157 -> 0 | D30: =Notes!$J$157 -> 0
A31: (c) Deferred Tax Assets (net) | C31: =Notes!$I$165 -> 0 | D31: =Notes!$J$165 -> 0
A32: (d) Other Non-current Assets | C32: =Notes!$I$173 -> 0 | D32: =Notes!$J$173 -> 0
A33: Total | C33: =SUM(C29:C32) -> 1234104.9 | D33: =SUM(D29:D32) -> 0
A35: (2) Current assets
A36: (a) Trade Receivables | B36: 12 | C36: =Notes!$I$195 -> 9813353.9 | D36: =Notes!$J$195 -> 0
A37: (b) Cash and cash equivalents | B37: 13 | C37: =Notes!$I$203 -> 150192.98 | D37: =Notes!$J$203 -> 0
A38: (c) Inventories | B38: 14 | C38: =Notes!$I$211 -> 0 | D38: =Notes!$J$211 -> 0
A39: (d) Other Current Assets | B39: 15 | C39: =Notes!$I$220 -> 396932 | D39: =Notes!$J$220 -> 0
A40: Total | C40: =SUM(C36:C39) -> 10360479 | D40: =SUM(D36:D39) -> 0
A42: Total Assets | C42: =SUM(C33,C40) -> 11594584 | D42: =SUM(D33,D40) -> 0 | E42: =C42-C24 -> 0
A44: See accompanying notes to the financial statements
A46: As per our report of even date
A47: For R.K.Tantry & Co., | B47: For and on behalf of the Partners of
A48: Chartered Accountants | B48: KRTRIMAIQ COGNITIVE SOLUTIONS
...

Sheet Fixed Assets
B2: KRTRIMAIQ COGNITIVE SOLUTIONS
B3: (Partnership Firm)
B4: Fixed Assets Schedule forming part of the Financial Statements
B6: Property, Plant and Equipment | L6: (In Rs)
B7: Name of Assets | C7: Gross Block | G7: Depreciation and Amortization | K7: Net Block | L7: Net Block
C8: As on | D8: Addition | E8: Deduction | F8: As on | G8: As on | H8: for the | I8: Deduction | J8: As on | K8: As on | L8: As on
C9: 45747 | F9: 46112 | G9: 45747 | H9: year | J9: 46112 | K9: 46112 | L9: 45747
B10: (i) Property, Plant and Equipment
B12: Computer- Laptop- IPad | C12: =TB!$B$116 -> 902257.32 | D12: =TB!$C$116 -> 84000 | E12: =TB!$D$116 -> 0 | F12: =C12+D12-E12 -> 986257.32 | G12: =0 -> 0 | H12: 0 | I12: =0 -> 0 | J12: =G12+H12-I12 -> 0 | K12: =F12-J12 -> 986257.32 | L12: =C12-G12 -> 902257.32
B13: Furniture and Fittings | C13: =TB!$B$117 -> 37201 | D13: =TB!$C$117 -> 0 | E13: =TB!$D$117 -> 0 | F13: =C13+D13-E13 -> 37201 | G13: =0 -> 0 | H13: 0 | I13: =0 -> 0 | J13: =G13+H13-I13 -> 0 | K13: =F13-J13 -> 37201 | L13: =C13-G13 -> 37201
B14: Mobile | C14: =TB!$B$118 -> 39683.6 | D14: =TB!$C$118 -> 0 | E14: =TB!$D$118 -> 0 | F14: =C14+D14-E14 -> 39683.6 | G14: =0 -> 0 | H14: 0 | I14: =0 -> 0 | J14: =G14+H14-I14 -> 0 | K14: =F14-J14 -> 39683.6 | L14: =C14-G14 -> 39683.6
B15: Office Equipments | C15: =TB!$B$119 -> 170963 | D15: =TB!$C$119 -> 0 | E15: =TB!$D$119 -> 0 | F15: =C15+D15-E15 -> 170963 | G15: =0 -> 0 | H15: 0 | I15: =0 -> 0 | J15: =G15+H15-I15 -> 0 | K15: =F15-J15 -> 170963 | L15: =C15-G15 -> 170963
B16: Total | C16: =SUM(C12:C15) -> 1150104.9 | D16: =SUM(D12:D15) -> 84000 | E16: =SUM(E12:E15) -> 0 | F16: =SUM(F12:F15) -> 1234104.9 | G16: =SUM(G12:G15) -> 0 | H16: =SUM(H12:H15) -> 0 | I16: =SUM(I12:I15) -> 0 | J16: =SUM(J12:J15) -> 0 | ... L16: =SUM(L12:L15) -> 1150104.9
B17: Previous Year

Sheet TB
A1: KRTRIMAIQ COGNITIVE SOLUTIONS - (2023-24)
A2: No. 98/A 3Rd Floor
A3: 30Th Cross,7Th Block Jayanagar
A4: Bangalore
A5: KARNATAKA
A6: 560082
A7: E-Mail : srinivasarao.poladi@krtri maiq.ai
A8: Trial Balance
A9: 1-Apr-25 to 31-Mar-26
A10: 9 | B10: KRTRIMAIQ COGNITIVE SOLUTIONS - (2023-24) - (from 1-Apr-24) - (from 1-Apr-25)
A11: Particulars | B11: 1-Apr-25 to 31-Mar-26
A12: 9 | B12: Opening | C12: Transactions | E12: Closing
A13: 9 | B13: Balance | C13: Debit | D13: Credit | E13: Balance
A14: Capital Account | B14: 9732791 | C14: 17133127 | D14: 5739336.1 | E14: 1661000.4
A15: Appropriation | C15: 2570893.2 | D15: 523992.84 | E15: 2046900.4
A16: Laxmi Poladi | B16: 1812735 | E16: 1812735
A17: Srinivas Rao Poladi | B17: 7920056 | C17: 1536715.2 | D17: 115343.23 | E17: 6498684
A18: Srinivas Rao Poladi - B1 Health | C18: 218775 | E18: 218775
A19: Srinivas Rao Poladi-Loan | D19: 5100000 | E19: 5100000
A20: Srinivas Rao Poladi - Sambhuthi | C20: 12806744 | E20: 12806744
A21: Current Liabilities | B21: 4727504.1 | C21: 71628266 | D21: 73573745 | E21: 6672982.9
A22: Duties & Taxes | B22: 90426 | C22: 8653328.2 | D22: 9298724.7 | E22: 735822.55
A23: CGST Input Tax | C23: 253369.33 | D23: 253369.33
A24: CGST Output Tax | C24: 2195020.1 | D24: 2195020.1
A25: GST Payable | B25: 90426 | C25: 3296167 | D25: 3941563.5 | E25: 735822.55
A26: IGST Input Tax | C26: 201182.32 | D26: 201182.32
A27: IGST Output Tax | C27: 259200 | D27: 259200
A28: SGST Input Tax | C28: 253369.33 | D28: 253369.33
A29: SGST Output Tax | C29: 2195020.1 | D29: 2195020.1
A30: Provisions | B30: 4661561 | C30: 58102964 | D30: 58855345 | E30: 5413941.3
A31: Expenses Payable | B31: 1711 | C31: 552694 | D31: 550983
A32: Akash Jena Expenses Payable | C32: 24566 | D32: 24566
A33: Arnab Ghosh Exp Payable | C33: 44183 | D33: 44183
A34: Arnav Kumar Exp | C34: 1776 | D34: 1776
A35: Arun Kumar K Exp Paybale | C35: 6316 | D35: 6316
A36: ASHISH SHUKLA Exp Paybale | C36: 17840 | D36: 17840
A37: Christy Joseph Exp Payable | C37: 38566 | D37: 38566
A38: Divyansh Chhablani Exp | B38: 1711 | C38: 16448 | D38: 14737
A39: Dushyant Chauhan Exp | C39: 800 | D39: 800
A40: Hemanth Ganta V V Expenses Payable | C40: 113064 | D40: 113064
...

Sheet Notes
A1: KRTRIMAIQ COGNITIVE SOLUTIONS
A3: (Partnership Firm)
A4: Notes forming part of the Financial Statements
A6: 1 | B6: Capital Account | J6: (In Rs)
B7: Particulars | I7: 46112 | J7: 45747
B9: Less: Appropriation | I9: =-TB!$E$15 -> -2046900.4 | J9: =-TB!$B$15 -> 0
B10: Laxmi Poladi | I10: =TB!$E$16 -> 1812735
B11: Srinivas Rao Poladi | I11: =TB!$E$17 -> 6498684
B12: Less: Srinivas Rao Poladi - B1 Health | I12: =-TB!$E$18 -> -218775 | J12: =-TB!$B$18 -> 0
B13: Less: Srinivas Rao Poladi - Sambhuthi | I13: =-TB!$E$20 -> -12806744 | J13: =-TB!$B$20 -> 0
B15: Total | I15: =SUM(I9:I13) -> -6761000.4
A18: 2 | B18: Profit and Loss Account | J18: (In Rs)
B19: Particulars | I19: 46112 | J19: 45747
B21: Current year surplus/(deficit) | I21: ='P&L'!$C$28 -> 6582601.3 | J21: =0 -> 0
B23: Total | I23: =SUM(I21:I21) -> 6582601.3 | J23: =SUM(J21:J21) -> 0
A26: 3 | B26: Long-term Borrowings | J26: (In Rs)
B27: Particulars | I27: 46112 | J27: 45747
B29: Srinivas Rao Poladi-Loan | I29: =TB!$E$19 -> 5100000 | J29: =TB!$B$19 -> 0
B31: Total | I31: =SUM(I29:I29) -> 5100000 | J31: =SUM(J29:J29) -> 0
A34: 4 | B34: Trade Payables | J34: (In Rs)
B35: Particulars | I35: 46112 | J35: 45747
B37: Due to Micro and Small Enterprises | I37: =0 -> 0 | J37: =0 -> 0
B38: Due to Others
B39: AINTREE TECH SOLUTIONS PRIVATE LIMITED | I39: =TB!$E$72 -> 0
B40: Amazon | I40: =TB!$E$73 -> 0 | J40: =TB!$B$73 -> 0
B41: AMAZON WEB SERVICES INDIA PRIVATE LIMITED | I41: =TB!$E$74 -> 0 | J41: =TB!$B$74 -> 0
B42: ANALYTICS INDIA MAGAZINE PRIVATE LIMITED | I42: =TB!$E$75 -> 0 | J42: =TB!$B$75 -> 0
B43: ANTHROPIC | I43: =TB!$E$76 -> 0 | J43: =TB!$B$76 -> 0
B44: APPYHAPPY SOFTWARE PRIVATE LIMITED | I44: =TB!$E$77 -> 0 | J44: =TB!$B$77 -> 0
B45: AUTHBRIDGE RESEARCH SERVICES PVT LTD | I45: =TB!$E$78 -> 0 | J45: =TB!$B$78 -> 0
B46: AV INFOLINE | I46: =TB!$E$79 -> 0 | J46: =TB!$B$79 -> 0
B47: BROWNE & MOHAN | I47: =TB!$E$80 -> 270000 | J47: =TB!$B$80 -> 0
B48: CARE HEALTH INSURANCE LIMITED | I48: =TB!$E$81 -> 0 | J48: =TB!$B$81 -> 0
B49: CLICKTECH RETAIL PRIVATE LIMITED | I49: =TB!$E$82 -> 0 | J49: =TB!$B$82 -> 0
B50: CONFEDERATION OF INDIAN INDUSTRY | I50: =TB!$E$83 -> 0 | J50: =TB!$B$83 -> 0
B51: E2E Networks Limited | I51: =TB!$E$84 -> 0
B52: Futura Digiral Colour Press | I52: =TB!$E$85 -> 0 | J52: =TB!$B$85 -> 0
B53: HDFC ERGO GENERAL INSURANCE COMPANY LIMITED | I53: =TB!$E$86 -> 0 | J53: =TB!$B$86 -> 0
B54: HEYGEN TECHNOLOGY INC | I54: =TB!$E$87 -> 0 | J54: =TB!$B$87 -> 0
B55: Interglobe Aviation Limited | I55: =TB!$E$88 -> 0 | J55: =TB!$B$88 -> 0
...
