Workbook

Sheet Balance Sheet
B1: Venus Agencies
B2: Balance Sheet AS AT 31.03.2026
B4: Particulars | C4: Note | D4: FY 2025-26 (₹) | E4: FY 2024-25 (₹)
B5: CAPITAL & LIABILITIES
B6: Owners' Funds | C6: 1 | D6: ='BS Schedules'!C18 -> 13674168 | E6: ='BS Schedules'!D18 -> 12525519
B7: Secured Borrowings | C7: 2 | D7: ='BS Schedules'!C22 -> 0 | E7: ='BS Schedules'!D22 -> 0
B8: Unsecured Borrowings | C8: 2 | D8: ='BS Schedules'!C23 -> 1669000 | E8: ='BS Schedules'!D23 -> 1669000
B9: Trade Payables | C9: 3 | D9: ='BS Schedules'!C28 -> 1985027.6 | E9: ='BS Schedules'!D28 -> 1697381
B10: Other Current Liabilities & Provisions | C10: 4 | D10: ='BS Schedules'!C34 -> 207.83 | E10: ='BS Schedules'!D34 -> 0
B11: Total Capital & Liabilities | D11: =SUM(D6:D10) -> 17328403 | E11: =SUM(E6:E10) -> 15891900
B13: ASSETS
B14: Property, Plant & Equipment | C14: 5 | D14: =PPE!H11 -> 3114689.6 | E14: =PPE!C11 -> 3145025
B15: Investments | C15: 6 | D15: ='BS Schedules'!C42 -> 750324 | E15: ='BS Schedules'!D42 -> 743296
B16: Inventories | C16: 7 | D16: ='BS Schedules'!C46 -> 4021447.3 | E16: ='BS Schedules'!D46 -> 3664516.5
B17: Trade Receivables | C17: 8 | D17: ='BS Schedules'!C50 -> 6720081.6 | E17: ='BS Schedules'!D50 -> 5626489
B18: Cash & Bank Balances | C18: 9 | D18: ='BS Schedules'!C58 -> 2221798.2 | E18: ='BS Schedules'!D58 -> 2270003.2
B19: Deposits | C19: 10 | D19: ='BS Schedules'!C66 -> 478348 | E19: ='BS Schedules'!D66 -> 435779
B20: Loans & Advances | C20: 11 | D20: ='BS Schedules'!C70 -> 20000 | E20: ='BS Schedules'!D70 -> 0
B21: Other Current Assets | C21: 12 | D21: ='BS Schedules'!C74 -> 1714.68 | E21: ='BS Schedules'!D76 -> 6791.02
B22: Total Assets | D22: =SUM(D14:D21) -> 17328403 | E22: =SUM(E14:E21) -> 15891900 | F22: =D11-D22 -> 0 | G22: =E11-E22 -> -0.2999
B26: For Venus Agencies | E26: For R.K.Tantry & co
E27: Chartered Accountants
E28: Firm Reg no.:004335S
E32: Partner :
E33: Radhakrishna Tantry
E34: Membership No.024012

Sheet Profit & Loss
B1: Venus Agencies
B2: Trading & Profit and Loss Account for the year ended 31.03.2026
B4: Particulars | C4: Note | D4: FY 2025-26 (₹) | E4: FY 2024-25 (₹)
B5: Revenue from Operations | C5: 13 | D5: ='P&L Notes'!C5 -> 84131053 | E5: ='P&L Notes'!D5 -> 95865039
B6: Less: Cost of Goods Sold | C6: 14 | D6: ='P&L Notes'!C17 -> 81561323 | E6: ='P&L Notes'!D17 -> 93086064
B7: Gross Profit / (Loss) | D7: =D5-D6 -> 2569730.1 | E7: =E5-E6 -> 2778975
B8: Add: Other Income | C8: 15 | D8: ='P&L Notes'!C9 -> 0 | E8: ='P&L Notes'!D9 -> 0
B9: Gross Profit / (Loss) incl. Other Income | D9: =D7+D8 -> 2569730.1 | E9: =E7+E8 -> 2778975
B10: Less: Operating & Other Expenses | C10: 16 | D10: ='P&L Notes'!C33 -> 881162.57 | E10: ='P&L Notes'!D33 -> 952497.58
B11: Less: Finance Costs | C11: 17 | D11: ='P&L Notes'!C38 -> 19041.61 | E11: ='P&L Notes'!D38 -> 25297.68
B12: Profit / (Loss) For The Period | D12: =D9-D10-D11 -> 1669525.9 | E12: =E9-E10-E11 -> 1801179.7
B16: ='Balance Sheet'!B26 -> For Venus Agencies | E16: For R.K.Tantry & co
E17: Chartered Accountants
E18: Firm Reg no.:004335S
E22: Partner :
E23: Radhakrishna Tantry
E24: Membership No.024012

Sheet BS Schedules
B1: BALANCE SHEET SCHEDULES – CONSOLIDATED
B3: NOTE 1 – OWNERS' CAPITAL ACCOUNT
B4: Particulars | C4: FY 2025-26 (₹) | D4: FY 2024-25 (₹)
B5: As per last Balance Sheet | C5: 12525518 | D5: 11401929
B6: Add:
B7: Profit for the year | C7: ='Profit & Loss'!D12 -> 1669525.9 | D7: 1801179.9
B8: Profit on sale of Sovereign Gold Bond | C8: =TB!C14 -> 65850 | D8: 0
B9: Interest on FD and NSC | C9: =TB!C16 -> 78607 | D9: =39376+50561 -> 89937
B10: SB Interest | C10: =(5101.88) -> 5101.88 | D10: 2595
B11: LIC income received | C11: 51346 | D11: 31222
B12: Total Additions | C12: =SUM(C7:C11) -> 1870430.8 | D12: =SUM(D7:D11) -> 1924933.9
B13: Less:
B14: Drawings | C14: =360000+45120+363+63073+195000 -> 663556 | D14: =360000+63073-33415+332057 -> 721715
B15: Health Insurance paid | C15: =51149 -> 51149 | D15: 57134
B16: LIC premium paid | C16: 7076 | D16: =1598+10453+10444 -> 22495
B17: Total Deductions | C17: =SUM(C14:C16) -> 721781 | D17: =SUM(D14:D16) -> 801344
B18: TOTAL - Owners' Capital Account | C18: =C5+C12-C17 -> 13674168 | D18: =D5+D12-D17 -> 12525519 | E18: =D18-C5 -> 0.4201
B20: NOTE 2 – BORROWINGS
B21: Particulars | C21: FY 2025-26 (₹) | D21: FY 2024-25 (₹)
B22: Secured Borrowings | C22: 0 | D22: 0
B23: Unsecured Borrowings | C23: =TB!C19 -> 1669000 | D23: 1669000
B24: Total Borrowings | C24: =SUM(C22:C23) -> 1669000 | D24: =SUM(D22:D23) -> 1669000
B26: NOTE 3 – TRADE PAYABLES
B27: Particulars | C27: FY 2025-26 (₹) | D27: FY 2024-25 (₹)
B28: Sundry Creditors / Trade Payables | C28: =TB!C24-TB!B24 -> 1985027.6 | D28: 1697381
B31: NOTE 4 – OTHER CURRENT LIABILITIES & PROVISIONS
B32: Particulars | C32: FY 2025-26 (₹) | D32: FY 2024-25 (₹)
B33: GST Payable | C33: =TB!C22 -> 207.83 | D33: 0
B34: Total Other Current Liabilities & Provisions | C34: =SUM(C33:C33) -> 207.83 | D34: =SUM(D33:D33) -> 0
B36: NOTE 6 - INVESTMENTS
B37: Particulars | C37: FY 2025-26 (₹) | D37: FY 2024-25 (₹)
B38: GMC Bank Shares | C38: =TB!B34 -> 45911 | D38: 45911
B39: Namasthe Co-Operative bank | C39: =TB!B35 -> 10250 | D39: 10250
B40: Gold Bond | C40: 0 | D40: 29010
B41: N.S.C | C41: =TB!B36 -> 694163 | D41: 658125
B42: Total Investments | C42: =SUM(C38:C41) -> 750324 | D42: =SUM(D38:D41) -> 743296
B44: NOTE 7 – INVENTORY
B45: Particulars | C45: FY 2025-26 (₹) | D45: FY 2024-25 (₹)
B46: Closing Stock / Inventory | C46: ='P&L Notes'!C16 -> 4021447.3 | D46: ='P&L Notes'!D16 -> 3664516.5
B48: NOTE 8 – TRADE RECEIVABLES
...

Sheet P&L Notes
B1: PROFIT & LOSS NOTES – CONSOLIDATED
B3: NOTE 13 – REVENUE FROM OPERATIONS
B4: Particulars | C4: FY 2025-26 (₹) | D4: FY 2024-25 (₹)
B5: Sales / Revenue from Operations | C5: =TB!C51 -> 84131053 | D5: 95865039
B7: NOTE 15 – OTHER INCOME
B8: Particulars | C8: FY 2025-26 (₹) | D8: FY 2024-25 (₹)
B9: Total Other Income | C9: 0 | D9: 0
B11: NOTE 14 – TRADING / COST OF GOODS SOLD
B12: Particulars | C12: FY 2025-26 (₹) | D12: FY 2024-25 (₹)
B13: Opening Stock | C13: =TB!B38 -> 3664516.5 | D13: 4279134.8
B14: Add: Purchases | C14: =TB!B56-TB!C56 -> 80602107 | D14: 91106620
B15: Add: Direct Expenses | C15: =TB!B63-TB!C63 -> 1316147.1 | D15: =200103+1164723 -> 1364826
B16: Less: Closing Stock | C16: =TB!B50+TB!C68 -> 4021447.3 | D16: 3664516.5
B17: Cost of Goods Sold | C17: =C13+C14-C16+C15 -> 81561323 | D17: =D13+D14-D16+D15 -> 93086064
B19: NOTE 16 – OPERATING & OTHER EXPENSES
B20: Particulars | C20: FY 2025-26 (₹) | D20: FY 2024-25 (₹)
B21: Audit Fees | C21: =TB!B70 -> 53600 | D21: 50000
B22: Electricity Charges | C22: =TB!B74 -> 2965 | D22: 8722
B23: Membership Fee | C23: =TB!B76 -> 5000 | D23: =2000+1500 -> 3500
B24: Salary Paid | C24: =TB!B77 -> 504000 | D24: 570000
B25: Shop Expenses | C25: =TB!B78 -> 101055 | D25: 108810
B26: Insurance Paid | C26: =3540+6080 -> 9620 | D26: 18435
B27: Tally Software Services | C27: =TB!B80 -> 6500 | D27: 0
B28: Telephone Charges | C28: =TB!B81 -> 31786.74 | D28: 27431.84
B29: Vehicle Maintainance | C29: =TB!B83 -> 104140.38 | D29: 101665.74
B30: Brokerage Charges | C30: 0 | D30: 5550
B31: Rates and Taxes | C31: =TB!B72+TB!B75 -> 27070 | D31: 17902
B32: Depreciation | C32: =PPE!G11 -> 35425.45 | D32: 40481
B33: Total Operating & Other Expenses | C33: =SUM(C21:C32) -> 881162.57 | D33: =SUM(D21:D32) -> 952497.58
B35: NOTE 17 – FINANCE COSTS
B36: Particulars | C36: FY 2025-26 (₹) | D36: FY 2024-25 (₹)
B37: Bank Charges | C37: =TB!B71 -> 19041.61 | D37: 25297.68
B38: Total Finance Costs | C38: =SUM(C37:C37) -> 19041.61 | D38: =SUM(D37:D37) -> 25297.68

Sheet PPE
B2: NOTE 5 – PROPERTY, PLANT & EQUIPMENT
B3: Particulars | C3: Opening Balance | D3: Addition upto 3-10-2025 | E3: Addition after 4-10-2025 | F3: Rate | G3: Depreciation | H3: Closing Balance
B4: Car | C4: 149721 | D4: 0 | E4: 0 | F4: 0.15 | G4: =((C4*F4)+(D4*F4)+((E4*F4))/2) -> 22458.15 | H4: =(C4+D4+E4)-G4 -> 127262.85
B5: Computer | C5: 23 | D5: 0 | E5: 5090 | F5: 0.4 | G5: =((C5*F5)+(D5*F5)+((E5*F5))/2) -> 1027.2 | H5: =(C5+D5+E5)-G5 -> 4085.8
B6: Furniture and Fixtures | C6: 601 | D6: 0 | E6: 0 | F6: 0.1 | G6: =((C6*F6)+(D6*F6)+((E6*F6))/2) -> 60.1 | H6: =(C6+D6+E6)-G6 -> 540.9
B7: Sanghavi Opera Flat(50% share) | C7: 1614925 | D7: 0 | E7: 0 | F7: 0 | G7: =((C7*F7)+(D7*F7)+((E7*F7))/2) -> 0 | H7: =(C7+D7+E7)-G7 -> 1614925
B8: Scooter | C8: 78329 | D8: 0 | E8: 0 | F8: 0.15 | G8: =((C8*F8)+(D8*F8)+((E8*F8))/2) -> 11749.35 | H8: =(C8+D8+E8)-G8 -> 66579.65
B9: Shop Building | C9: 1300555 | D9: 0 | E9: 0 | F9: 0 | G9: =((C9*F9)+(D9*F9)+((E9*F9))/2) -> 0 | H9: =(C9+D9+E9)-G9 -> 1300555
B10: Weighing Scale | C10: 871 | D10: 0 | E10: 0 | F10: 0.15 | G10: =((C10*F10)+(D10*F10)+((E10*F10))/2) -> 130.65 | H10: =(C10+D10+E10)-G10 -> 740.35
B11: Total | C11: =SUM(C4:C10) -> 3145025 | D11: =SUM(D4:D10) -> 0 | E11: =SUM(E4:E10) -> 5090 | F11: 0 | G11: =SUM(G4:G10) -> 35425.45 | H11: =SUM(H4:H10) -> 3114689.6

Sheet TB
A1: venus agencies 2025-26
A2: 14/30 M.G.B.COMPLEX
A3: APMC YARD YPR
A4: BANGALORE-560022
A5: G.S.Tin No.29ABGPV9302D1ZH
A6: Trial Balance
A7: 1-Apr-25 to 31-Mar-26
B8: venus agencies 2025-26
A9: Particulars | B9: 1-Apr-25 to 31-Mar-26
B10: Closing Balance
B11: Debit | C11: Credit
A12: Capital Account | B12: 195000 | C12: 12199642
A13: Advance Income Tax | B13: 195000
A14: Capital Gain on Sale on Gold Bond | C14: 65850
A15: GODS A/C | C15: 3384
A16: Interest on FD | C16: 78607
A17: T L Venkatesh | C17: 12051801
A18: Loans (Liability) | C18: 1669000
A19: T.L.Venkatesh (H.U.F ) | C19: 1669000
A20: Current Liabilities | B20: 56780.68 | C20: 2040301.4
A21: Duties & Taxes | B21: 1714.68 | C21: 207.83
A22: G S T | C22: 207.83
A23: R.M.C .60% | B23: 1714.68
A24: Sundry Creditors | B24: 55066 | C24: 2040093.6
A25: Fixed Assets | B25: 3114690
A26: Car Accunnt | B26: 127263
A27: Computer A/C | B27: 4086
A28: Furnitures & Fixtures | B28: 541
A29: Sanghavi Opera Flat (50% Share) | B29: 1614925
A30: Scooter | B30: 66580
A31: Shop Building | B31: 1300555
A32: Weighing Scale A/C | B32: 740
A33: Investments | B33: 750324
A34: G.M.C.Bank Shares A/C | B34: 45911
A35: NAMASTE CO-OPERATIVE BANK (SHARES) | B35: 10250
A36: N.S.C | B36: 694163
... A50: Inventory Difference Account | B50: 623000
A51: Sales Accounts | C51: 84131053
A52: Gst Sales @ 5% | C52: 13990194
A53: Gst Sales Nil Rated | C53: 68484429
...

Sheet Accounting policies
A1: Venus Agencies
A2: SIGNIFICANT ACCOUNTING POLICIES
A4: a. | B4: BASIS OF PREPARATION OF FINANCIAL STATEMENTS
B5: The Financial Statements are prepared on accrual basis under the historical cost convention (except where impairment is made and revaluation is carried out) on the basis of going concern and is in accordance with Accounting Standards issued by the Institute of Chartered Accountants of India.
A7: b. | B7: USE OF ESTIMATES
B8: In preparing the Financial Statements in conformity with accounting principles generally accepted in India, the Assessee is required to make estimates and assumptions that affect the reported amounts of assets and liabilities and the disclosure of contingent liabilities as at the date of the Financial Statements and the amounts of revenue and expenses during the reported period. Actual results could differ from those estimates. Any revision to such estimates is recognised in the period the same is determined.
A10: c. | B10: PROPERTY, PLANT & EQUIPMENT
B11: The cost of Tangible Property, Plant & Equipment is recognised as Property, Plant and Equipment if it is probable that the future economic benefit associated with the item will flow to the entity and the cost can be reliably measured. Property, Plant & Equipment are stated at cost of acquisition or construction and, in case of revaluation of assets, at revalued amounts net of impairment loss if any, less depreciation. Cost represents direct expenses incurred on acquisition or construction of the assets and the share of indirect expenses relating to construction allocated in proportion to the direct cost involved. Such costs shall be added by any subsequent costs incurred to replace a part or service it, if it increases the economic life of the asset and such costs are reliably measurable. Any subsequent cost that does not meet the above recognition criteria is charged to the statement of profit and loss.
A13: d. | B13: DEPRECIATION
B14: Depreciation on assets is provided at the rates as specified by the Income Tax Act, 1961, however it is computed on each asset component separately and not as block of assets.
A16: e. | B16: INVESTMENTS
B17: Investments held by the Assessee which are long term in nature are stated at cost unless there is any permanent diminution in value where provision for diminution is made on individual investment basis. Current investments are valued at cost or market price or fair value, whichever is lower. Earnings on investments are accounted for on accrual basis.
A19: f. | B19: INVENTORIES
B20: Inventory of Raw Materials valued at cost or net realisable value, whichever is lower. Cost of raw material includes all charges in bringing the goods to the premises including transportation and other incidental charges.
A22: g. | B22: BORROWING COSTS
B23: Borrowing cost includes interest and amortization of ancillary costs incurred in connection with the arrangement of borrowings. Borrowing costs directly attributable to the acquisition, construction or production of an asset that necessarily takes a substantial period of time to get ready for its intended use or sale are capitalized as part of the cost of the respective asset. All other borrowing costs are expensed in the period they occur.
A25: h. | B25: PROVISIONS, CONTINGENT LIABILITIES AND CONTINGENT ASSETS
B26: Provisions are recognised when there is a present legal or statutory obligation as a result of past events and where it is probable that there will be outflow of resources to settle the obligation and when a reliable estimate of the amount of the obligation can be made. Contingent Liabilities are recognised only when there is a possible obligation arising from past events due to occurrence or non-occurrence of one or more uncertain future events not wholly within the control of the entity or where any present obligation cannot be measured in terms of future outflow of resources or where a reliable estimate of the obligation cannot be made. Obligations are assessed on an ongoing basis and only those having a largely probable outflow of resources are provided for. Contingent Assets are not recognised in the Financial Statements.
